Workbook

Sheet Read Me
A1: PlySpy: 3-ply delivered toilet paper value tracker
A3: How to use this workbook
A5: 1 | B5: Enter products on the Listings sheet. The workbook only ranks products where ply = 3, in_stock = Yes, delivery_available = Yes, and sheet count is known.
A6: 2 | B6: Use 'Standalone order' when toilet paper is the only item being delivered. Use 'Grocery add-on' when you were already doing a grocery shop and delivery should not be counted.
A7: 3 | B7: The Dashboard pulls the top 10 by adjusted_value_score. Lower score = better value.
A8: 4 | B8: No dynamic array formulas are used, so this version should open cleanly in Excel for Mac/Windows.
A9: 5 | B9: For real comparisons, replace the demo rows with actual product listings and source URLs.

Sheet Listings
A1: date_checked | B1: retailer | C1: product_name | D1: brand | E1: url | F1: pack_price | G1: member_price | H1: effective_price | I1: delivery_mode | J1: delivery_fee | K1: small_order_charge | L1: delivered_price | M1: rolls_per_pack | N1: sheets_per_roll | O1: total_sheets | P1: ply | Q1: sheet_width_mm | R1: sheet_length_mm | S1: sheet_area_m2 | T1: total_area_m2 | U1: price_per_roll | V1: price_per_100_sheets | W1: price_per_m2 | X1: rating | Y1: review_count | Z1: in_stock | AA1: delivery_available | AB1: total_sheets_source | AC1: data_confidence | AD1: include_status | AE1: quality_multiplier | AF1: adjusted_value_score | AG1: rank | AH1: last_verified | AI1: notes
A2: 46185 | B2: Aldi | C2: Saxon Premium Toilet Paper | D2: Saxon | E2: https://www.aldi.co.uk/product/saxon-premium-toilet-paper-12-pack-000000000000632047 | F2: 4.99 | H2: =IF(F2="","",IF(G2="",F2,G2)) -> 4.99 | I2: Standalone order | J2: 0 | K2: 0 | L2: =IF(H2="","",IF(I2="Grocery add-on",H2,H2+N(J2)+N(K2))) -> 4.99 | M2: 12 | N2: 320 | O2: =IF(OR(M2="",N2=""),"",M2*N2) -> 3840 | P2: 3 | S2: =IF(OR(Q2="",R2=""),"",Q2*R2/1000000) | T2: =IF(OR(O2="",S2=""),"",O2*S2) | U2: =IFERROR(L2/M2,"") -> 0.41583333 | V2: =IFERROR(L2/O2*100,"") -> 0.12994792 | W2: =IFERROR(L2/T2,"") | Z2: Yes | AA2: Yes | AB2: Direct | AC2: =IF(A2="","",IF(AND(H2<>"",M2<>"",N2<>"",P2=3,Z2="Yes",AA2="Yes"),"High",IF(AND(H2<>"",M2<>"",N2<>""),"Medium","Low"))) -> High | AD2: =IF(AND(P2>=3,Z2="Yes",AA2="Yes",O2<>"",L2<>""),"Include","Exclude") -> Include | AE2: =IF(A2="","",IF(OR(ListingsTable[[#This Row],[rating]]="",ListingsTable[[#This Row],[review_count]]=""),1.03,IF(ListingsTable[[#This Row],[review_count]]<10,1,IF(ListingsTable[[#This Row],[rating]]>=4.5,0.95,IF(ListingsTable[[#This Row],[rating]]>=4,1,IF(ListingsTable[[#This Row],[rating]]<3.8,1.05,1)))))) -> 1.03 | AF2: =IF(AD2="Include",V2*AE2,"") -> 0.13384635 | AG2: =IF(AF2="","",COUNTIFS($AF$2:$AF$76,"<"&AF2,$AD$2:$AD$76,"Include")+COUNTIFS($AF$2:AF2,AF2,$AD$2:AD2,"Include")) -> 1
A3: 46188 | B3: Amazon | C3: Lusheen Soft Quilted Toilet Rolls Bulk Buy | D3: Lusheen | E3: https://www.amazon.co.uk/Lusheen-Soft-Quilted-Toilet-Rolls/dp/B0FS1XXWCP/ref=sr_1_62?dib=eyJ2IjoiMSJ9.zLBvAWWN9LXeSGaNKgq_kwu6K1tlIUQdQ3a_4ewJtlE4qQ5y8DlucRLVp_it6y2lT9Uysy5s91Jtpyca3GJsv58AKGjDe5GuyTokuf0pLuT1_rCCxETb1BiZpYsPLtCwLawjed9U8b5A8Pydxb_3mMxg_sDdo6U5pXdELasD7ydsMqXbqDle7JsKTYxfiF0s12xowJD9FwgD3Abj05V9F1FQU1bviCm5doI-7Iu2zPERwvnjX9Ke7E-Mf-2ELd1tbut23mbKYpXSXH0lIOAFQnrwfonOaq4np4WztNOX5T4.wrBMswEacn4pfixDjRlhv2_T6bhTNv02JKGWJOoCHCw&dib_tag=se&keywords=toilet+rolls+3ply&qid=1781348762&xpid=FjHbdT4PCS1_n | F3: 9.99 | H3: =IF(F3="","",IF(G3="",F3,G3)) -> 9.99 | I3: Standalone order | J3: 0 | K3: 0 | L3: =IF(H3="","",IF(I3="Grocery add-on",H3,H3+N(J3)+N(K3))) -> 9.99 | M3: 45 | N3: 155 | O3: =IF(OR(M3="",N3=""),"",M3*N3) -> 6975 | P3: 3 | S3: =IF(OR(Q3="",R3=""),"",Q3*R3/1000000) | T3: =IF(OR(O3="",S3=""),"",O3*S3) | U3: =IFERROR(L3/M3,"") -> 0.222 | V3: =IFERROR(L3/O3*100,"") -> 0.14322581 | W3: =IFERROR(L3/T3,"") | X3: 5 | Y3: 2 | Z3: Yes | AA3: Yes | AB3: Direct | AC3: =IF(A3="","",IF(AND(H3<>"",M3<>"",N3<>"",P3=3,Z3="Yes",AA3="Yes"),"High",IF(AND(H3<>"",M3<>"",N3<>""),"Medium","Low"))) -> High | AD3: =IF(AND(P3>=3,Z3="Yes",AA3="Yes",O3<>"",L3<>""),"Include","Exclude") -> Include | AE3: =IF(A3="","",IF(OR(ListingsTable[[#This Row],[rating]]="",ListingsTable[[#This Row],[review_count]]=""),1.03,IF(ListingsTable[[#This Row],[review_count]]<10,1,IF(ListingsTable[[#This Row],[rating]]>=4.5,0.95,IF(ListingsTable[[#This Row],[rating]]>=4,1,IF(ListingsTable[[#This Row],[rating]]<3.8,1.05,1)))))) -> 1 | AF3: =IF(AD3="Include",V3*AE3,"") -> 0.14322581 | AG3: =IF(AF3="","",COUNTIFS($AF$2:$AF$76,"<"&AF3,$AD$2:$AD$76,"Include")+COUNTIFS($AF$2:AF3,AF3,$AD$2:AD3,"Include")) -> 2
A4: 46185 | B4: Home Bargains | C4: Nicky Elite Quilted 3 Ply Toilet Rolls 64 Pack | D4: Nicky | E4: https://home.bargains/product/661dc0c2-2147-4d26-ad99-1334b3c19db4/nicky-elite-quilted-3-ply-toilet-rolls-64-pack-delivery-included?qid=f75f1b64a41775a62f475de1c55991cc | F4: 17.98 | H4: 17.98 | I4: Standalone order | J4: 0 | K4: 0 | L4: =IF(H4="","",IF(I4="Grocery add-on",H4,H4+N(J4)+N(K4))) -> 17.98 | M4: 64 | N4: 200 | O4: =IF(OR(M4="",N4=""),"",M4*N4) -> 12800 | P4: 3 | S4: =IF(OR(Q4="",R4=""),"",Q4*R4/1000000) | T4: =IF(OR(O4="",S4=""),"",O4*S4) | U4: =IFERROR(L4/M4,"") -> 0.2809375 | V4: =IFERROR(L4/O4*100,"") -> 0.14046875 | W4: =IFERROR(L4/T4,"") | Z4: Yes | AA4: Yes | AB4: Direct | AC4: =IF(A4="","",IF(AND(H4<>"",M4<>"",N4<>"",P4=3,Z4="Yes",AA4="Yes"),"High",IF(AND(H4<>"",M4<>"",N4<>""),"Medium","Low"))) -> High | AD4: =IF(AND(P4>=3,Z4="Yes",AA4="Yes",O4<>"",L4<>""),"Include","Exclude") -> Include | AE4: =IF(A4="","",IF(OR(ListingsTable[[#This Row],[rating]]="",ListingsTable[[#This Row],[review_count]]=""),1.03,IF(ListingsTable[[#This Row],[review_count]]<10,1,IF(ListingsTable[[#This Row],[rating]]>=4.5,0.95,IF(ListingsTable[[#This Row],[rating]]>=4,1,IF(ListingsTable[[#This Row],[rating]]<3.8,1.05,1)))))) -> 1.03 | AF4: =IF(AD4="Include",V4*AE4,"") -> 0.14468281 | AG4: =IF(AF4="","",COUNTIFS($AF$2:$AF$76,"<"&AF4,$AD$2:$AD$76,"Include")+COUNTIFS($AF$2:AF4,AF4,$AD$2:AD4,"Include")) -> 3
A5: 46185 | B5: Tesco | C5: Little Duck Supreme Quilted Toilet Tissue | D5: Little Duck | E5: https://www.tesco.com/shop/en-GB/products/321034855?_gl=1*sk0av2*_up*MQ..*_ga*Njg3NDQwODQyLjE3ODEzMDY1OTI.*_ga_H653QXESTP*czE3ODEzMDY1ODkkbzEkZzAkdDE3ODEzMDY1OTEkajU4JGwwJGg2MzYzNjI3Mjg.*_ga_33B19D36CY*czE3ODEzMDY1OTEkbzEkZzEkdDE3ODEzMDY5MTEkajYwJGwwJGgxNTA2NjcyMjk0 | F5: 6 | H5: =IF(F5="","",IF(G5="",F5,G5)) -> 6 | I5: Standalone order | J5: 0 | K5: 0 | L5: =IF(H5="","",IF(I5="Grocery add-on",H5,H5+N(J5)+N(K5))) -> 6 | M5: 16 | N5: 240 | O5: =IF(OR(M5="",N5=""),"",M5*N5) -> 3840 | P5: 3 | S5: =IF(OR(Q5="",R5=""),"",Q5*R5/1000000) | T5: =IF(OR(O5="",S5=""),"",O5*S5) | U5: =IFERROR(L5/M5,"") -> 0.375 | V5: =IFERROR(L5/O5*100,"") -> 0.15625 | W5: =IFERROR(L5/T5,"") | X5: 3.2 | Y5: 63 | Z5: Yes | AA5: Yes | AB5: Direct | AC5: =IF(A5="","",IF(AND(H5<>"",M5<>"",N5<>"",P5=3,Z5="Yes",AA5="Yes"),"High",IF(AND(H5<>"",M5<>"",N5<>""),"Medium","Low"))) -> High | AD5: =IF(AND(P5>=3,Z5="Yes",AA5="Yes",O5<>"",L5<>""),"Include","Exclude") -> Include | AE5: =IF(A5="","",IF(OR(ListingsTable[[#This Row],[rating]]="",ListingsTable[[#This Row],[review_count]]=""),1.03,IF(ListingsTable[[#This Row],[review_count]]<10,1,IF(ListingsTable[[#This Row],[rating]]>=4.5,0.95,IF(ListingsTable[[#This Row],[rating]]>=4,1,IF(ListingsTable[[#This Row],[rating]]<3.8,1.05,1)))))) -> 1.05 | AF5: =IF(AD5="Include",V5*AE5,"") -> 0.1640625 | AG5: =IF(AF5="","",COUNTIFS($AF$2:$AF$76,"<"&AF5,$AD$2:$AD$76,"Include")+COUNTIFS($AF$2:AF5,AF5,$AD$2:AD5,"Include")) -> 4
A6: 46188 | B6: Amazon | C6: Serenity Toilet Rolls | D6: Serenity | E6: https://www.amazon.co.uk/dp/B0F9X2GWGG/ref=sspa_dk_detail_3?pd_rd_i=B0F9X2GWGG&pd_rd_w=YFjNz&content-id=amzn1.sym.2f04b396-4cf6-4c10-837f-e222197e3b38&pf_rd_p=2f04b396-4cf6-4c10-837f-e222197e3b38&pf_rd_r=ZNA7W733GQ76FAY9A47Y&pd_rd_wg=KCuZj&pd_rd_r=9a025201-41a8-4ecb-8339-9caf239e3056&aref=GjSls8fb7p&sp_csd=d2lkZ2V0TmFtZT1zcF9kZXRhaWxfdGhlbWF0aWM&th=1 | F6: 18.99 | H6: =IF(F6="","",IF(G6="",F6,G6)) -> 18.99 | I6: Standalone order | J6: 0 | K6: 0 | L6: =IF(H6="","",IF(I6="Grocery add-on",H6,H6+N(J6)+N(K6))) -> 18.99 | M6: 72 | N6: 160 | O6: =IF(OR(M6="",N6=""),"",M6*N6) -> 11520 | P6: 3 | Q6: 104 | R6: 107 | S6: =IF(OR(Q6="",R6=""),"",Q6*R6/1000000) -> 0.011128 | T6: =IF(OR(O6="",S6=""),"",O6*S6) -> 128.19456 | U6: =IFERROR(L6/M6,"") -> 0.26375 | V6: =IFERROR(L6/O6*100,"") -> 0.16484375 | W6: =IFERROR(L6/T6,"") -> 0.14813421 | X6: 4.2 | Y6: 477 | Z6: Yes | AA6: Yes | AB6: Direct | AC6: =IF(A6="","",IF(AND(H6<>"",M6<>"",N6<>"",P6=3,Z6="Yes",AA6="Yes"),"High",IF(AND(H6<>"",M6<>"",N6<>""),"Medium","Low"))) -> High | AD6: =IF(AND(P6>=3,Z6="Yes",AA6="Yes",O6<>"",L6<>""),"Include","Exclude") -> Include | AE6: =IF(A6="","",IF(OR(ListingsTable[[#This Row],[rating]]="",ListingsTable[[#This Row],[review_count]]=""),1.03,IF(ListingsTable[[#This Row],[review_count]]<10,1,IF(ListingsTable[[#This Row],[rating]]>=4.5,0.95,IF(ListingsTable[[#This Row],[rating]]>=4,1,IF(ListingsTable[[#This Row],[rating]]<3.8,1.05,1)))))) -> 1 | AF6: =IF(AD6="Include",V6*AE6,"") -> 0.16484375 | AG6: =IF(AF6="","",COUNTIFS($AF$2:$AF$76,"<"&AF6,$AD$2:$AD$76,"Include")+COUNTIFS($AF$2:AF6,AF6,$AD$2:AD6,"Include")) -> 5
A7: 46185 | B7: Home Bargains | C7: Premium Comfy Soft Quilted 3 Ply Toilet Tissue | D7: Premium Comfy | E7: https://home.bargains/product/82ee3af9-627d-4995-9914-a93fa929d359/premium-comfy-soft-quilted-3-ply-toilet-tissue-24-rolls-x3-delivery-included?qid=f75f1b64a41775a62f475de1c55991cc | F7: 18.99 | H7: =IF(F7="","",IF(G7="",F7,G7)) -> 18.99 | I7: Standalone order | J7: 0 | K7: 0 | L7: =IF(H7="","",IF(I7="Grocery add-on",H7,H7+N(J7)+N(K7))) -> 18.99 | M7: 72 | N7: 160 | O7: =IF(OR(M7="",N7=""),"",M7*N7) -> 11520 | P7: 3 | Q7: 115 | R7: 105 | S7: =IF(OR(Q7="",R7=""),"",Q7*R7/1000000) -> 0.012075 | T7: =IF(OR(O7="",S7=""),"",O7*S7) -> 139.104 | U7: =IFERROR(L7/M7,"") -> 0.26375 | V7: =IFERROR(L7/O7*100,"") -> 0.16484375 | W7: =IFERROR(L7/T7,"") -> 0.13651656 | Z7: Yes | AA7: Yes | AB7: Direct | AC7: =IF(A7="","",IF(AND(H7<>"",M7<>"",N7<>"",P7=3,Z7="Yes",AA7="Yes"),"High",IF(AND(H7<>"",M7<>"",N7<>""),"Medium","Low"))) -> High | AD7: =IF(AND(P7>=3,Z7="Yes",AA7="Yes",O7<>"",L7<>""),"Include","Exclude") -> Include | AE7: =IF(A7="","",IF(OR(ListingsTable[[#This Row],[rating]]="",ListingsTable[[#This Row],[review_count]]=""),1.03,IF(ListingsTable[[#This Row],[review_count]]<10,1,IF(ListingsTable[[#This Row],[rating]]>=4.5,0.95,IF(ListingsTable[[#This Row],[rating]]>=4,1,IF(ListingsTable[[#This Row],[rating]]<3.8,1.05,1)))))) -> 1.03 | AF7: =IF(AD7="Include",V7*AE7,"") -> 0.16978906 | AG7: =IF(AF7="","",COUNTIFS($AF$2:$AF$76,"<"&AF7,$AD$2:$AD$76,"Include")+COUNTIFS($AF$2:AF7,AF7,$AD$2:AD7,"Include")) -> 6
A8: 46188 | B8: Amazon | C8: Serenity Toilet Tissue | D8: Serenity | E8: https://www.amazon.co.uk/Serenity-Quilted-Luxuriously-Hypoallergenic-Sustainable/dp/B0DZ18FKFY/ref=sr_1_13_sspa?dib=eyJ2IjoiMSJ9.0VrQIYFNkddqjafxnBR4YTeWgT5cLGR5Y8SPipAYeZS7pFul15p3BNZPd_roKbmNl9KhjGGNEDuDFHWeP6gZK3n554gP9GbeOL7U6C9yEYVshr-m1kTidS7YVXLWWw8AaLPFGJWLKYZq4oftUEF_sYbAfbLrgnQChJRXcNYBXpD8kBom22EdiTv9sy8TAzYdXzr7vaec0trGkYXh8cxLh-UrEUvkYocXltZ4T1_IDxgnO91LF_hDl_Gv_unq777iVpJKCaDCRyz2vRRT3upJJXWAGp_rvuI7HVkbnVW4ZZM.Z9LHQyKSlJpjdNFJrgAVwXrwtwqWXrNRFB5oyJ00uso&dib_tag=se&keywords=toilet%2Brolls%2B3ply&qid=1781348685&sr=8-13-spons&aref=rwCRoscNUH&sp_csd=d2lkZ2V0TmFtZT1zcF9tdGY&th=1 | F8: 14.15 | H8: =IF(F8="","",IF(G8="",F8,G8)) -> 14.15 | I8: Standalone order | J8: 0 | K8: 0 | L8: =IF(H8="","",IF(I8="Grocery add-on",H8,H8+N(J8)+N(K8))) -> 14.15 | M8: 54 | N8: 150 | O8: =IF(OR(M8="",N8=""),"",M8*N8) -> 8100 | P8: 3 | S8: =IF(OR(Q8="",R8=""),"",Q8*R8/1000000) | T8: =IF(OR(O8="",S8=""),"",O8*S8) | U8: =IFERROR(L8/M8,"") -> 0.26203704 | V8: =IFERROR(L8/O8*100,"") -> 0.17469136 | W8: =IFERROR(L8/T8,"") | X8: 4.4 | Y8: 233 | Z8: Yes | AA8: Yes | AB8: Direct | AC8: =IF(A8="","",IF(AND(H8<>"",M8<>"",N8<>"",P8=3,Z8="Yes",AA8="Yes"),"High",IF(AND(H8<>"",M8<>"",N8<>""),"Medium","Low"))) -> High | AD8: =IF(AND(P8>=3,Z8="Yes",AA8="Yes",O8<>"",L8<>""),"Include","Exclude") -> Include | AE8: =IF(A8="","",IF(OR(ListingsTable[[#This Row],[rating]]="",ListingsTable[[#This Row],[review_count]]=""),1.03,IF(ListingsTable[[#This Row],[review_count]]<10,1,IF(ListingsTable[[#This Row],[rating]]>=4.5,0.95,IF(ListingsTable[[#This Row],[rating]]>=4,1,IF(ListingsTable[[#This Row],[rating]]<3.8,1.05,1)))))) -> 1 | AF8: =IF(AD8="Include",V8*AE8,"") -> 0.17469136 | AG8: =IF(AF8="","",COUNTIFS($AF$2:$AF$76,"<"&AF8,$AD$2:$AD$76,"Include")+COUNTIFS($AF$2:AF8,AF8,$AD$2:AD8,"Include")) -> 7
A9: 46188 | B9: Amazon | C9: Softlux Toilet Rolls | D9: Softlux | E9: https://www.amazon.co.uk/Softlux-Toilet-Embossed-Quilted-Unscented/dp/B0GMJZL6T8/ref=sr_1_84?dib=eyJ2IjoiMSJ9.zLBvAWWN9LXeSGaNKgq_kwu6K1tlIUQdQ3a_4ewJtlE4qQ5y8DlucRLVp_it6y2lT9Uysy5s91Jtpyca3GJsv58AKGjDe5GuyTokuf0pLuT1_rCCxETb1BiZpYsPLtCwLawjed9U8b5A8Pydxb_3mMxg_sDdo6U5pXdELasD7ydsMqXbqDle7JsKTYxfiF0s12xowJD9FwgD3Abj05V9F1FQU1bviCm5doI-7Iu2zPERwvnjX9Ke7E-Mf-2ELd1tbut23mbKYpXSXH0lIOAFQnrwfonOaq4np4WztNOX5T4.wrBMswEacn4pfixDjRlhv2_T6bhTNv02JKGWJOoCHCw&dib_tag=se&keywords=toilet+rolls+3ply&qid=1781348762&xpid=FjHbdT4PCS1_n | F9: 25.49 | H9: =IF(F9="","",IF(G9="",F9,G9)) -> 25.49 | I9: Standalone order | J9: 0 | K9: 0 | L9: =IF(H9="","",IF(I9="Grocery add-on",H9,H9+N(J9)+N(K9))) -> 25.49 | M9: 120 | N9: 120 | O9: =IF(OR(M9="",N9=""),"",M9*N9) -> 14400 | P9: 3 | S9: =IF(OR(Q9="",R9=""),"",Q9*R9/1000000) | T9: =IF(OR(O9="",S9=""),"",O9*S9) | U9: =IFERROR(L9/M9,"") -> 0.21241667 | V9: =IFERROR(L9/O9*100,"") -> 0.17701389 | W9: =IFERROR(L9/T9,"") | X9: 4.3 | Y9: 18 | Z9: Yes | AA9: Yes | AB9: Direct | AC9: =IF(A9="","",IF(AND(H9<>"",M9<>"",N9<>"",P9=3,Z9="Yes",AA9="Yes"),"High",IF(AND(H9<>"",M9<>"",N9<>""),"Medium","Low"))) -> High | AD9: =IF(AND(P9>=3,Z9="Yes",AA9="Yes",O9<>"",L9<>""),"Include","Exclude") -> Include | AE9: =IF(A9="","",IF(OR(ListingsTable[[#This Row],[rating]]="",ListingsTable[[#This Row],[review_count]]=""),1.03,IF(ListingsTable[[#This Row],[review_count]]<10,1,IF(ListingsTable[[#This Row],[rating]]>=4.5,0.95,IF(ListingsTable[[#This Row],[rating]]>=4,1,IF(ListingsTable[[#This Row],[rating]]<3.8,1.05,1)))))) -> 1 | AF9: =IF(AD9="Include",V9*AE9,"") -> 0.17701389 | AG9: =IF(AF9="","",COUNTIFS($AF$2:$AF$76,"<"&AF9,$AD$2:$AD$76,"Include")+COUNTIFS($AF$2:AF9,AF9,$AD$2:AD9,"Include")) -> 8
A10: 46185 | B10: Morrisons | C10: Elegance Gentle Quilted Toilet Paper | D10: Elegance | E10: https://groceries.morrisons.com/products/elegance-gentle-quilted-toilet-paper-24-pack/113348943 | F10: 6.5 | H10: =IF(F10="","",IF(G10="",F10,G10)) -> 6.5 | I10: Standalone order | J10: 0 | K10: 0 | L10: =IF(H10="","",IF(I10="Grocery add-on",H10,H10+N(J10)+N(K10))) -> 6.5 | M10: 24 | N10: 160 | O10: =IF(OR(M10="",N10=""),"",M10*N10) -> 3840 | P10: 3 | Q10: 110 | R10: 96 | S10: =IF(OR(Q10="",R10=""),"",Q10*R10/1000000) -> 0.01056 | T10: =IF(OR(O10="",S10=""),"",O10*S10) -> 40.5504 | U10: =IFERROR(L10/M10,"") -> 0.27083333 | V10: =IFERROR(L10/O10*100,"") -> 0.16927083 | W10: =IFERROR(L10/T10,"") -> 0.16029435 | X10: 3.7 | Y10: 28 | Z10: Yes | AA10: Yes | AB10: Direct | AC10: =IF(A10="","",IF(AND(H10<>"",M10<>"",N10<>"",P10=3,Z10="Yes",AA10="Yes"),"High",IF(AND(H10<>"",M10<>"",N10<>""),"Medium","Low"))) -> High | AD10: =IF(AND(P10>=3,Z10="Yes",AA10="Yes",O10<>"",L10<>""),"Include","Exclude") -> Include | AE10: =IF(A10="","",IF(OR(ListingsTable[[#This Row],[rating]]="",ListingsTable[[#This Row],[review_count]]=""),1.03,IF(ListingsTable[[#This Row],[review_count]]<10,1,IF(ListingsTable[[#This Row],[rating]]>=4.5,0.95,IF(ListingsTable[[#This Row],[rating]]>=4,1,IF(ListingsTable[[#This Row],[rating]]<3.8,1.05,1)))))) -> 1.05 | AF10: =IF(AD10="Include",V10*AE10,"") -> 0.17773438 | AG10: =IF(AF10="","",COUNTIFS($AF$2:$AF$76,"<"&AF10,$AD$2:$AD$76,"Include")+COUNTIFS($AF$2:AF10,AF10,$AD$2:AD10,"Include")) -> 9
A11: 46188 | B11: Amazon | C11: Eloquence Super Soft Luxuriously Quilted Toilet Tissue Rolls | D11: Eloquence | E11: https://www.amazon.co.uk/Eloquence-Luxuriously-Carefully-Manufactured-Certified/dp/B0GCWW9SLH/ref=sr_1_104?dib=eyJ2IjoiMSJ9.0aKA_PMLIKi2qGTchC6dPM5zhv8QsLw5eUUuDlCSE_fciUTE0oVddZ7NNloM0K-kT9TfCodEDyPi97i00T3eKQDFnA5_sVmcnAjpT7sw9YeRI-stOQCHUaKr9uHkw8uLqJaQbjwE3RYh-mL_1dAvjGWh3f9KlQ0Tf_-utSX-4MrlcYA5jXUL5eeX2WJNsr6V00EpqfrEXfjbhCqqZfmmG3pFt9JnDVJmN3he0e56IBi-Ou8B8eM1tIoPirzfizNAfJbmX96Q6ofLwnboOt2irCSCGUCqO7ZPjjqn83S6mnY.w6hjR7-hjluwhACGaPledFpWgPZmiomJwu0HguJEeWc&dib_tag=se&keywords=toilet+rolls+3ply&qid=1781537902&xpid=FjHbdT4PCS1_n | F11: 18.49 | H11: =IF(F11="","",IF(G11="",F11,G11)) -> 18.49 | I11: Standalone order | J11: 0 | K11: 0 | L11: =IF(H11="","",IF(I11="Grocery add-on",H11,H11+N(J11)+N(K11))) -> 18.49 | M11: 60 | N11: 170 | O11: =IF(OR(M11="",N11=""),"",M11*N11) -> 10200 | P11: 3 | S11: =IF(OR(Q11="",R11=""),"",Q11*R11/1000000) | T11: =IF(OR(O11="",S11=""),"",O11*S11) | U11: =IFERROR(L11/M11,"") -> 0.30816667 | V11: =IFERROR(L11/O11*100,"") -> 0.18127451 | W11: =IFERROR(L11/T11,"") | X11: 4.6 | Y11: 7 | Z11: Yes | AA11: Yes | AB11: Direct | AC11: =IF(A11="","",IF(AND(H11<>"",M11<>"",N11<>"",P11=3,Z11="Yes",AA11="Yes"),"High",IF(AND(H11<>"",M11<>"",N11<>""),"Medium","Low"))) -> High | AD11: =IF(AND(P11>=3,Z11="Yes",AA11="Yes",O11<>"",L11<>""),"Include","Exclude") -> Include | AE11: =IF(A11="","",IF(OR(ListingsTable[[#This Row],[rating]]="",ListingsTable[[#This Row],[review_count]]=""),1.03,IF(ListingsTable[[#This Row],[review_count]]<10,1,IF(ListingsTable[[#This Row],[rating]]>=4.5,0.95,IF(ListingsTable[[#This Row],[rating]]>=4,1,IF(ListingsTable[[#This Row],[rating]]<3.8,1.05,1)))))) -> 1 | AF11: =IF(AD11="Include",V11*AE11,"") -> 0.18127451 | AG11: =IF(AF11="","",COUNTIFS($AF$2:$AF$76,"<"&AF11,$AD$2:$AD$76,"Include")+COUNTIFS($AF$2:AF11,AF11,$AD$2:AD11,"Include")) -> 10
A12: 46188 | B12: Amazon | C12: Softesse Toilet Paper | D12: Softesse | E12: https://www.amazon.co.uk/Softesse-Toilet-Luxuriously-Hypoallergenic-Sustainable/dp/B0DWT6GRRM/ref=sr_1_22?dib=eyJ2IjoiMSJ9.0VrQIYFNkddqjafxnBR4YTeWgT5cLGR5Y8SPipAYeZS7pFul15p3BNZPd_roKbmNl9KhjGGNEDuDFHWeP6gZK3n554gP9GbeOL7U6C9yEYVshr-m1kTidS7YVXLWWw8AaLPFGJWLKYZq4oftUEF_sYbAfbLrgnQChJRXcNYBXpD8kBom22EdiTv9sy8TAzYdXzr7vaec0trGkYXh8cxLh-UrEUvkYocXltZ4T1_IDxgnO91LF_hDl_Gv_unq777iVpJKCaDCRyz2vRRT3upJJXWAGp_rvuI7HVkbnVW4ZZM.Z9LHQyKSlJpjdNFJrgAVwXrwtwqWXrNRFB5oyJ00uso&dib_tag=se&keywords=toilet%2Brolls%2B3ply&qid=1781348685&sr=8-22&th=1 | F12: 17.99 | H12: =IF(F12="","",IF(G12="",F12,G12)) -> 17.99 | I12: Standalone order | J12: 0 | K12: 0 | L12: =IF(H12="","",IF(I12="Grocery add-on",H12,H12+N(J12)+N(K12))) -> 17.99 | M12: 60 | N12: 160 | O12: =IF(OR(M12="",N12=""),"",M12*N12) -> 9600 | P12: 3 | S12: =IF(OR(Q12="",R12=""),"",Q12*R12/1000000) | T12: =IF(OR(O12="",S12=""),"",O12*S12) | U12: =IFERROR(L12/M12,"") -> 0.29983333 | V12: =IFERROR(L12/O12*100,"") -> 0.18739583 | W12: =IFERROR(L12/T12,"") | X12: 4.3 | Y12: 1772 | Z12: Yes | AA12: Yes | AB12: Direct | AC12: =IF(A12="","",IF(AND(H12<>"",M12<>"",N12<>"",P12=3,Z12="Yes",AA12="Yes"),"High",IF(AND(H12<>"",M12<>"",N12<>""),"Medium","Low"))) -> High | AD12: =IF(AND(P12>=3,Z12="Yes",AA12="Yes",O12<>"",L12<>""),"Include","Exclude") -> Include | AE12: =IF(A12="","",IF(OR(ListingsTable[[#This Row],[rating]]="",ListingsTable[[#This Row],[review_count]]=""),1.03,IF(ListingsTable[[#This Row],[review_count]]<10,1,IF(ListingsTable[[#This Row],[rating]]>=4.5,0.95,IF(ListingsTable[[#This Row],[rating]]>=4,1,IF(ListingsTable[[#This Row],[rating]]<3.8,1.05,1)))))) -> 1 | AF12: =IF(AD12="Include",V12*AE12,"") -> 0.18739583 | AG12: =IF(AF12="","",COUNTIFS($AF$2:$AF$76,"<"&AF12,$AD$2:$AD$76,"Include")+COUNTIFS($AF$2:AF12,AF12,$AD$2:AD12,"Include")) -> 11
A13: 46188 | B13: Amazon | C13: Panda Cuddle 3‑Ply Quilted Toilet Paper | D13: Panda | E13: https://www.amazon.co.uk/Panda-Cuddle-3%E2%80%91Ply-Quilted-Toilet/dp/B0F8S37RGW/ref=sr_1_28?dib=eyJ2IjoiMSJ9.0VrQIYFNkddqjafxnBR4YTeWgT5cLGR5Y8SPipAYeZS7pFul15p3BNZPd_roKbmNl9KhjGGNEDuDFHWeP6gZK3n554gP9GbeOL7U6C9yEYVshr-m1kTidS7YVXLWWw8AaLPFGJWLKYZq4oftUEF_sYbAfbLrgnQChJRXcNYBXpD8kBom22EdiTv9sy8TAzYdXzr7vaec0trGkYXh8cxLh-UrEUvkYocXltZ4T1_IDxgnO91LF_hDl_Gv_unq777iVpJKCaDCRyz2vRRT3upJJXWAGp_rvuI7HVkbnVW4ZZM.Z9LHQyKSlJpjdNFJrgAVwXrwtwqWXrNRFB5oyJ00uso&dib_tag=se&keywords=toilet%2Brolls%2B3ply&qid=1781348685&sr=8-28&th=1 | F13: 23.75 | H13: =IF(F13="","",IF(G13="",F13,G13)) -> 23.75 | I13: Standalone order | J13: 0 | K13: 0 | L13: =IF(H13="","",IF(I13="Grocery add-on",H13,H13+N(J13)+N(K13))) -> 23.75 | M13: 90 | N13: 140 | O13: =IF(OR(M13="",N13=""),"",M13*N13) -> 12600 | P13: 3 | S13: =IF(OR(Q13="",R13=""),"",Q13*R13/1000000) | T13: =IF(OR(O13="",S13=""),"",O13*S13) | U13: =IFERROR(L13/M13,"") -> 0.26388889 | V13: =IFERROR(L13/O13*100,"") -> 0.18849206 | W13: =IFERROR(L13/T13,"") | X13: 4.4 | Y13: 789 | Z13: Yes | AA13: Yes | AB13: Direct | AC13: =IF(A13="","",IF(AND(H13<>"",M13<>"",N13<>"",P13=3,Z13="Yes",AA13="Yes"),"High",IF(AND(H13<>"",M13<>"",N13<>""),"Medium","Low"))) -> High | AD13: =IF(AND(P13>=3,Z13="Yes",AA13="Yes",O13<>"",L13<>""),"Include","Exclude") -> Include | AE13: =IF(A13="","",IF(OR(ListingsTable[[#This Row],[rating]]="",ListingsTable[[#This Row],[review_count]]=""),1.03,IF(ListingsTable[[#This Row],[review_count]]<10,1,IF(ListingsTable[[#This Row],[rating]]>=4.5,0.95,IF(ListingsTable[[#This Row],[rating]]>=4,1,IF(ListingsTable[[#This Row],[rating]]<3.8,1.05,1)))))) -> 1 | AF13: =IF(AD13="Include",V13*AE13,"") -> 0.18849206 | AG13: =IF(AF13="","",COUNTIFS($AF$2:$AF$76,"<"&AF13,$AD$2:$AD$76,"Include")+COUNTIFS($AF$2:AF13,AF13,$AD$2:AD13,"Include")) -> 12
A14: 46188 | B14: Amazon | C14: DHANZIPAK Premium Quilted Toilet Paper | D14: DHANZIPAK | E14: https://www.amazon.co.uk/DHANZIPAK-Premium-Generous-Luxuriously-Absorbent/dp/B0DVRMTRPS/ref=sr_1_20_sspa?dib=eyJ2IjoiMSJ9.0VrQIYFNkddqjafxnBR4YTeWgT5cLGR5Y8SPipAYeZS7pFul15p3BNZPd_roKbmNl9KhjGGNEDuDFHWeP6gZK3n554gP9GbeOL7U6C9yEYVshr-m1kTidS7YVXLWWw8AaLPFGJWLKYZq4oftUEF_sYbAfbLrgnQChJRXcNYBXpD8kBom22EdiTv9sy8TAzYdXzr7vaec0trGkYXh8cxLh-UrEUvkYocXltZ4T1_IDxgnO91LF_hDl_Gv_unq777iVpJKCaDCRyz2vRRT3upJJXWAGp_rvuI7HVkbnVW4ZZM.Z9LHQyKSlJpjdNFJrgAVwXrwtwqWXrNRFB5oyJ00uso&dib_tag=se&keywords=toilet+rolls+3ply&qid=1781348685&sr=8-20-spons&aref=USNn1RsYDR&sp_csd=d2lkZ2V0TmFtZT1zcF9tdGY&psc=1 | F14: 16.99 | H14: =IF(F14="","",IF(G14="",F14,G14)) -> 16.99 | I14: Standalone order | J14: 0 | K14: 0 | L14: =IF(H14="","",IF(I14="Grocery add-on",H14,H14+N(J14)+N(K14))) -> 16.99 | M14: 54 | N14: 165 | O14: =IF(OR(M14="",N14=""),"",M14*N14) -> 8910 | P14: 3 | Q14: 95 | R14: 110 | S14: =IF(OR(Q14="",R14=""),"",Q14*R14/1000000) -> 0.01045 | T14: =IF(OR(O14="",S14=""),"",O14*S14) -> 93.1095 | U14: =IFERROR(L14/M14,"") -> 0.31462963 | V14: =IFERROR(L14/O14*100,"") -> 0.19068462 | W14: =IFERROR(L14/T14,"") -> 0.18247332 | X14: 4.2 | Y14: 254 | Z14: Yes | AA14: Yes | AB14: Direct | AC14: =IF(A14="","",IF(AND(H14<>"",M14<>"",N14<>"",P14=3,Z14="Yes",AA14="Yes"),"High",IF(AND(H14<>"",M14<>"",N14<>""),"Medium","Low"))) -> High | AD14: =IF(AND(P14>=3,Z14="Yes",AA14="Yes",O14<>"",L14<>""),"Include","Exclude") -> Include | AE14: =IF(A14="","",IF(OR(ListingsTable[[#This Row],[rating]]="",ListingsTable[[#This Row],[review_count]]=""),1.03,IF(ListingsTable[[#This Row],[review_count]]<10,1,IF(ListingsTable[[#This Row],[rating]]>=4.5,0.95,IF(ListingsTable[[#This Row],[rating]]>=4,1,IF(ListingsTable[[#This Row],[rating]]<3.8,1.05,1)))))) -> 1 | AF14: =IF(AD14="Include",V14*AE14,"") -> 0.19068462 | AG14: =IF(AF14="","",COUNTIFS($AF$2:$AF$76,"<"&AF14,$AD$2:$AD$76,"Include")+COUNTIFS($AF$2:AF14,AF14,$AD$2:AD14,"Include")) -> 13
A15: 46188 | B15: Amazon | C15: Gentille Quilted Bathroom Tissue Rolls | D15: Gentille | E15: https://www.amazon.co.uk/Gentille-Quilted-Bathroom-Tissue-Sustainable/dp/B0DRSXS64G/ref=sr_1_104?dib=eyJ2IjoiMSJ9.L9V_5TPJj1d4Orl59f-a3Fd0aTJAM1y3O1UF7rTtnme-gEqQjNRgrOFGqESwcK11bhQYxPuRD1DzPbhGgnzjtvvIquUXRxFuklmhVjoW5p4.nD_ubALX6aBUq8d0NaOShgAoWRurMYzFndWPIWVNtSg&dib_tag=se&keywords=toilet%2Brolls%2B3ply&qid=1781537902&xpid=FjHbdT4PCS1_n&th=1 | F15: 25 | H15: =IF(F15="","",IF(G15="",F15,G15)) -> 25 | I15: Standalone order | J15: 0 | K15: 0 | L15: =IF(H15="","",IF(I15="Grocery add-on",H15,H15+N(J15)+N(K15))) -> 25 | M15: 96 | N15: 135 | O15: =IF(OR(M15="",N15=""),"",M15*N15) -> 12960 | P15: 3 | S15: =IF(OR(Q15="",R15=""),"",Q15*R15/1000000) | T15: =IF(OR(O15="",S15=""),"",O15*S15) | U15: =IFERROR(L15/M15,"") -> 0.26041667 | V15: =IFERROR(L15/O15*100,"") -> 0.19290123 | W15: =IFERROR(L15/T15,"") | X15: 4.3 | Y15: 3365 | Z15: Yes | AA15: Yes | AB15: Direct | AC15: =IF(A15="","",IF(AND(H15<>"",M15<>"",N15<>"",P15=3,Z15="Yes",AA15="Yes"),"High",IF(AND(H15<>"",M15<>"",N15<>""),"Medium","Low"))) -> High | AD15: =IF(AND(P15>=3,Z15="Yes",AA15="Yes",O15<>"",L15<>""),"Include","Exclude") -> Include | AE15: =IF(A15="","",IF(OR(ListingsTable[[#This Row],[rating]]="",ListingsTable[[#This Row],[review_count]]=""),1.03,IF(ListingsTable[[#This Row],[review_count]]<10,1,IF(ListingsTable[[#This Row],[rating]]>=4.5,0.95,IF(ListingsTable[[#This Row],[rating]]>=4,1,IF(ListingsTable[[#This Row],[rating]]<3.8,1.05,1)))))) -> 1 | AF15: =IF(AD15="Include",V15*AE15,"") -> 0.19290123 | AG15: =IF(AF15="","",COUNTIFS($AF$2:$AF$76,"<"&AF15,$AD$2:$AD$76,"Include")+COUNTIFS($AF$2:AF15,AF15,$AD$2:AD15,"Include")) -> 14
A16: 46188 | B16: Amazon | C16: AmazonCommercial Toilet Roll | D16: Amazon | E16: https://www.amazon.co.uk/AmazonCommercial-Premium-Toilet-Tissue-rolls/dp/B08C61HFLD/ref=sr_1_91?dib=eyJ2IjoiMSJ9.zLBvAWWN9LXeSGaNKgq_kwu6K1tlIUQdQ3a_4ewJtlE4qQ5y8DlucRLVp_it6y2lT9Uysy5s91Jtpyca3GJsv58AKGjDe5GuyTokuf0pLuT1_rCCxETb1BiZpYsPLtCwLawjed9U8b5A8Pydxb_3mMxg_sDdo6U5pXdELasD7ydsMqXbqDle7JsKTYxfiF0s12xowJD9FwgD3Abj05V9F1FQU1bviCm5doI-7Iu2zPERwvnjX9Ke7E-Mf-2ELd1tbut23mbKYpXSXH0lIOAFQnrwfonOaq4np4WztNOX5T4.wrBMswEacn4pfixDjRlhv2_T6bhTNv02JKGWJOoCHCw&dib_tag=se&keywords=toilet%2Brolls%2B3ply&qid=1781348762&rdc=1&xpid=FjHbdT4PCS1_n&th=1 | F16: 34.59 | H16: =IF(F16="","",IF(G16="",F16,G16)) -> 34.59 | I16: Standalone order | J16: 0 | K16: 0 | L16: =IF(H16="","",IF(I16="Grocery add-on",H16,H16+N(J16)+N(K16))) -> 34.59 | M16: 72 | N16: 243 | O16: =IF(OR(M16="",N16=""),"",M16*N16) -> 17496 | P16: 3 | Q16: 94.6 | R16: 110 | S16: =IF(OR(Q16="",R16=""),"",Q16*R16/1000000) -> 0.010406 | T16: =IF(OR(O16="",S16=""),"",O16*S16) -> 182.06338 | U16: =IFERROR(L16/M16,"") -> 0.48041667 | V16: =IFERROR(L16/O16*100,"") -> 0.19770233 | W16: =IFERROR(L16/T16,"") -> 0.18998879 | X16: 4.4 | Y16: 1908 | Z16: Yes | AA16: Yes | AB16: Direct | AC16: =IF(A16="","",IF(AND(H16<>"",M16<>"",N16<>"",P16=3,Z16="Yes",AA16="Yes"),"High",IF(AND(H16<>"",M16<>"",N16<>""),"Medium","Low"))) -> High | AD16: =IF(AND(P16>=3,Z16="Yes",AA16="Yes",O16<>"",L16<>""),"Include","Exclude") -> Include | AE16: =IF(A16="","",IF(OR(ListingsTable[[#This Row],[rating]]="",ListingsTable[[#This Row],[review_count]]=""),1.03,IF(ListingsTable[[#This Row],[review_count]]<10,1,IF(ListingsTable[[#This Row],[rating]]>=4.5,0.95,IF(ListingsTable[[#This Row],[rating]]>=4,1,IF(ListingsTable[[#This Row],[rating]]<3.8,1.05,1)))))) -> 1 | AF16: =IF(AD16="Include",V16*AE16,"") -> 0.19770233 | AG16: =IF(AF16="","",COUNTIFS($AF$2:$AF$76,"<"&AF16,$AD$2:$AD$76,"Include")+COUNTIFS($AF$2:AF16,AF16,$AD$2:AD16,"Include")) -> 15
A17: 46185 | B17: Home Bargains | C17: Nicky Elite Quilted 3 Ply Toilet Rolls 18 Pack x4 | D17: Nicky | E17: https://home.bargains/product/9cec7f2d-557e-48ac-9f68-2d007f1e470d/nicky-elite-quilted-3-ply-toilet-rolls-18-pack-x4-delivery-included?qid=f75f1b64a41775a62f475de1c55991cc | F17: 23.92 | H17: =IF(F17="","",IF(G17="",F17,G17)) -> 23.92 | I17: Standalone order | J17: 0 | K17: 0 | L17: =IF(H17="","",IF(I17="Grocery add-on",H17,H17+N(J17)+N(K17))) -> 23.92 | M17: 72 | N17: 170 | O17: =IF(OR(M17="",N17=""),"",M17*N17) -> 12240 | P17: 3 | S17: =IF(OR(Q17="",R17=""),"",Q17*R17/1000000) | T17: =IF(OR(O17="",S17=""),"",O17*S17) | U17: =IFERROR(L17/M17,"") -> 0.33222222 | V17: =IFERROR(L17/O17*100,"") -> 0.19542484 | W17: =IFERROR(L17/T17,"") | Z17: Yes | AA17: Yes | AB17: Direct | AC17: =IF(A17="","",IF(AND(H17<>"",M17<>"",N17<>"",P17=3,Z17="Yes",AA17="Yes"),"High",IF(AND(H17<>"",M17<>"",N17<>""),"Medium","Low"))) -> High | AD17: =IF(AND(P17>=3,Z17="Yes",AA17="Yes",O17<>"",L17<>""),"Include","Exclude") -> Include | AE17: =IF(A17="","",IF(OR(ListingsTable[[#This Row],[rating]]="",ListingsTable[[#This Row],[review_count]]=""),1.03,IF(ListingsTable[[#This Row],[review_count]]<10,1,IF(ListingsTable[[#This Row],[rating]]>=4.5,0.95,IF(ListingsTable[[#This Row],[rating]]>=4,1,IF(ListingsTable[[#This Row],[rating]]<3.8,1.05,1)))))) -> 1.03 | AF17: =IF(AD17="Include",V17*AE17,"") -> 0.20128758 | AG17: =IF(AF17="","",COUNTIFS($AF$2:$AF$76,"<"&AF17,$AD$2:$AD$76,"Include")+COUNTIFS($AF$2:AF17,AF17,$AD$2:AD17,"Include")) -> 16
A18: 46185 | B18: Amazon | C18: by Amazon Toilet Roll | D18: Amazon | E18: https://www.amazon.co.uk/Amazon-Brand-Presto-Toilet-Tissues/dp/B08JDBBL9T/ref=sr_1_11_ffob_sspa?dib=eyJ2IjoiMSJ9.0VrQIYFNkddqjafxnBR4YTeWgT5cLGR5Y8SPipAYeZS7pFul15p3BNZPd_roKbmNl9KhjGGNEDuDFHWeP6gZK3n554gP9GbeOL7U6C9yEYVshr-m1kTidS7YVXLWWw8AaLPFGJWLKYZq4oftUEF_sYbAfbLrgnQChJRXcNYBXpD8kBom22EdiTv9sy8TAzYdXzr7vaec0trGkYXh8cxLh-UrEUvkYocXltZ4T1_IDxgnO91LF_hDl_Gv_unq777iVpJKCaDCRyz2vRRT3upJJXWAGp_rvuI7HVkbnVW4ZZM.Z9LHQyKSlJpjdNFJrgAVwXrwtwqWXrNRFB5oyJ00uso&dib_tag=se&keywords=toilet+rolls+3ply&qid=1781348685&rdc=1&sr=8-11-spons&aref=JmmPoa8Lx4&sp_csd=d2lkZ2V0TmFtZT1zcF9tdGY&psc=1 | F18: 18.47 | H18: =IF(F18="","",IF(G18="",F18,G18)) -> 18.47 | I18: Standalone order | J18: 0 | K18: 0 | L18: =IF(H18="","",IF(I18="Grocery add-on",H18,H18+N(J18)+N(K18))) -> 18.47 | M18: 45 | N18: 200 | O18: =IF(OR(M18="",N18=""),"",M18*N18) -> 9000 | P18: 3 | S18: =IF(OR(Q18="",R18=""),"",Q18*R18/1000000) | T18: =IF(OR(O18="",S18=""),"",O18*S18) | U18: =IFERROR(L18/M18,"") -> 0.41044444 | V18: =IFERROR(L18/O18*100,"") -> 0.20522222 | W18: =IFERROR(L18/T18,"") | X18: 4.4 | Y18: 1112 | Z18: Yes | AA18: Yes | AB18: Direct | AC18: =IF(A18="","",IF(AND(H18<>"",M18<>"",N18<>"",P18=3,Z18="Yes",AA18="Yes"),"High",IF(AND(H18<>"",M18<>"",N18<>""),"Medium","Low"))) -> High | AD18: =IF(AND(P18>=3,Z18="Yes",AA18="Yes",O18<>"",L18<>""),"Include","Exclude") -> Include | AE18: =IF(A18="","",IF(OR(ListingsTable[[#This Row],[rating]]="",ListingsTable[[#This Row],[review_count]]=""),1.03,IF(ListingsTable[[#This Row],[review_count]]<10,1,IF(ListingsTable[[#This Row],[rating]]>=4.5,0.95,IF(ListingsTable[[#This Row],[rating]]>=4,1,IF(ListingsTable[[#This Row],[rating]]<3.8,1.05,1)))))) -> 1 | AF18: =IF(AD18="Include",V18*AE18,"") -> 0.20522222 | AG18: =IF(AF18="","",COUNTIFS($AF$2:$AF$76,"<"&AF18,$AD$2:$AD$76,"Include")+COUNTIFS($AF$2:AF18,AF18,$AD$2:AD18,"Include")) -> 17
A19: 46185 | B19: Aldi | C19: Saxon Quilted Toilet Paper | D19: Saxon | E19: https://www.aldi.co.uk/product/saxon-quilted-toilet-paper-9-pack-000000000000648727 | F19: 2.99 | H19: =IF(F19="","",IF(G19="",F19,G19)) -> 2.99 | I19: Standalone order | J19: 0 | K19: 0 | L19: =IF(H19="","",IF(I19="Grocery add-on",H19,H19+N(J19)+N(K19))) -> 2.99 | M19: 9 | N19: 160 | O19: =IF(OR(M19="",N19=""),"",M19*N19) -> 1440 | P19: 3 | S19: =IF(OR(Q19="",R19=""),"",Q19*R19/1000000) | T19: =IF(OR(O19="",S19=""),"",O19*S19) | U19: =IFERROR(L19/M19,"") -> 0.33222222 | V19: =IFERROR(L19/O19*100,"") -> 0.20763889 | W19: =IFERROR(L19/T19,"") | Z19: Yes | AA19: Yes | AB19: Direct | AC19: =IF(A19="","",IF(AND(H19<>"",M19<>"",N19<>"",P19=3,Z19="Yes",AA19="Yes"),"High",IF(AND(H19<>"",M19<>"",N19<>""),"Medium","Low"))) -> High | AD19: =IF(AND(P19>=3,Z19="Yes",AA19="Yes",O19<>"",L19<>""),"Include","Exclude") -> Include | AE19: =IF(A19="","",IF(OR(ListingsTable[[#This Row],[rating]]="",ListingsTable[[#This Row],[review_count]]=""),1.03,IF(ListingsTable[[#This Row],[review_count]]<10,1,IF(ListingsTable[[#This Row],[rating]]>=4.5,0.95,IF(ListingsTable[[#This Row],[rating]]>=4,1,IF(ListingsTable[[#This Row],[rating]]<3.8,1.05,1)))))) -> 1.03 | AF19: =IF(AD19="Include",V19*AE19,"") -> 0.21386806 | AG19: =IF(AF19="","",COUNTIFS($AF$2:$AF$76,"<"&AF19,$AD$2:$AD$76,"Include")+COUNTIFS($AF$2:AF19,AF19,$AD$2:AD19,"Include")) -> 18
A20: 46185 | B20: Tesco Marketplace | C20: Freedom Inspirations Quilted Soft White 3 Ply Toilet Paper Roll | D20: Freedom | E20: https://www.tesco.com/shop/en-GB/products/330659961?seller=trn:tesco:seller:uuid:3ca332f5-c2df-406a-af90-1e145d277929&_gl=1*1pg7u36*_up*MQ..*_ga*Njg3NDQwODQyLjE3ODEzMDY1OTI.*_ga_H653QXESTP*czE3ODEzMDY1ODkkbzEkZzAkdDE3ODEzMDY1OTEkajU4JGwwJGg2MzYzNjI3Mjg.*_ga_33B19D36CY*czE3ODEzMDY1OTEkbzEkZzEkdDE3ODEzMDY2MTYkajM1JGwwJGgxNTA2NjcyMjk0 | F20: 15.49 | H20: =IF(F20="","",IF(G20="",F20,G20)) -> 15.49 | I20: Standalone order | J20: 0 | K20: 0 | L20: =IF(H20="","",IF(I20="Grocery add-on",H20,H20+N(J20)+N(K20))) -> 15.49 | M20: 45 | N20: 160 | O20: =IF(OR(M20="",N20=""),"",M20*N20) -> 7200 | P20: 3 | S20: =IF(OR(Q20="",R20=""),"",Q20*R20/1000000) | T20: =IF(OR(O20="",S20=""),"",O20*S20) | U20: =IFERROR(L20/M20,"") -> 0.34422222 | V20: =IFERROR(L20/O20*100,"") -> 0.21513889 | W20: =IFERROR(L20/T20,"") | X20: 4.5 | Y20: 2 | Z20: Yes | AA20: Yes | AB20: Direct | AC20: =IF(A20="","",IF(AND(H20<>"",M20<>"",N20<>"",P20=3,Z20="Yes",AA20="Yes"),"High",IF(AND(H20<>"",M20<>"",N20<>""),"Medium","Low"))) -> High | AD20: =IF(AND(P20>=3,Z20="Yes",AA20="Yes",O20<>"",L20<>""),"Include","Exclude") -> Include | AE20: =IF(A20="","",IF(OR(ListingsTable[[#This Row],[rating]]="",ListingsTable[[#This Row],[review_count]]=""),1.03,IF(ListingsTable[[#This Row],[review_count]]<10,1,IF(ListingsTable[[#This Row],[rating]]>=4.5,0.95,IF(ListingsTable[[#This Row],[rating]]>=4,1,IF(ListingsTable[[#This Row],[rating]]<3.8,1.05,1)))))) -> 1 | AF20: =IF(AD20="Include",V20*AE20,"") -> 0.21513889 | AG20: =IF(AF20="","",COUNTIFS($AF$2:$AF$76,"<"&AF20,$AD$2:$AD$76,"Include")+COUNTIFS($AF$2:AF20,AF20,$AD$2:AD20,"Include")) -> 19
A21: 46188 | B21: Amazon | C21: evoXL Luxury 3-Ply Toilet Tissue | D21: evoXL | E21: https://www.amazon.co.uk/evoXL-Luxury-3-Ply-Toilet-Tissue/dp/B0G1CPJN6T/ref=sr_1_53?dib=eyJ2IjoiMSJ9.zLBvAWWN9LXeSGaNKgq_kwu6K1tlIUQdQ3a_4ewJtlE4qQ5y8DlucRLVp_it6y2lT9Uysy5s91Jtpyca3GJsv58AKGjDe5GuyTokuf0pLuT1_rCCxETb1BiZpYsPLtCwLawjed9U8b5A8Pydxb_3mMxg_sDdo6U5pXdELasD7ydsMqXbqDle7JsKTYxfiF0s12xowJD9FwgD3Abj05V9F1FQU1bviCm5doI-7Iu2zPERwvnjX9Ke7E-Mf-2ELd1tbut23mbKYpXSXH0lIOAFQnrwfonOaq4np4WztNOX5T4.wrBMswEacn4pfixDjRlhv2_T6bhTNv02JKGWJOoCHCw&dib_tag=se&keywords=toilet+rolls+3ply&qid=1781348762&xpid=FjHbdT4PCS1_n | F21: 16.99 | H21: =IF(F21="","",IF(G21="",F21,G21)) -> 16.99 | I21: Standalone order | J21: 0 | K21: 0 | L21: =IF(H21="","",IF(I21="Grocery add-on",H21,H21+N(J21)+N(K21))) -> 16.99 | M21: 60 | N21: 130 | O21: =IF(OR(M21="",N21=""),"",M21*N21) -> 7800 | P21: 3 | S21: =IF(OR(Q21="",R21=""),"",Q21*R21/1000000) | T21: =IF(OR(O21="",S21=""),"",O21*S21) | U21: =IFERROR(L21/M21,"") -> 0.28316667 | V21: =IFERROR(L21/O21*100,"") -> 0.21782051 | W21: =IFERROR(L21/T21,"") | X21: 4.2 | Y21: 38 | Z21: Yes | AA21: Yes | AB21: Direct | AC21: =IF(A21="","",IF(AND(H21<>"",M21<>"",N21<>"",P21=3,Z21="Yes",AA21="Yes"),"High",IF(AND(H21<>"",M21<>"",N21<>""),"Medium","Low"))) -> High | AD21: =IF(AND(P21>=3,Z21="Yes",AA21="Yes",O21<>"",L21<>""),"Include","Exclude") -> Include | AE21: =IF(A21="","",IF(OR(ListingsTable[[#This Row],[rating]]="",ListingsTable[[#This Row],[review_count]]=""),1.03,IF(ListingsTable[[#This Row],[review_count]]<10,1,IF(ListingsTable[[#This Row],[rating]]>=4.5,0.95,IF(ListingsTable[[#This Row],[rating]]>=4,1,IF(ListingsTable[[#This Row],[rating]]<3.8,1.05,1)))))) -> 1 | AF21: =IF(AD21="Include",V21*AE21,"") -> 0.21782051 | AG21: =IF(AF21="","",COUNTIFS($AF$2:$AF$76,"<"&AF21,$AD$2:$AD$76,"Include")+COUNTIFS($AF$2:AF21,AF21,$AD$2:AD21,"Include")) -> 20
A22: 46188 | B22: Amazon | C22: value plus Quilted & Embossed Toilet Paper with Coconut | D22: value plus | E22: https://www.amazon.co.uk/Value-Plus-Quilted-Embossed-Bathroom/dp/B0FX51C56S/ref=sr_1_94?dib=eyJ2IjoiMSJ9.zLBvAWWN9LXeSGaNKgq_kwu6K1tlIUQdQ3a_4ewJtlE4qQ5y8DlucRLVp_it6y2lT9Uysy5s91Jtpyca3GJsv58AKGjDe5GuyTokuf0pLuT1_rCCxETb1BiZpYsPLtCwLawjed9U8b5A8Pydxb_3mMxg_sDdo6U5pXdELasD7ydsMqXbqDle7JsKTYxfiF0s12xowJD9FwgD3Abj05V9F1FQU1bviCm5doI-7Iu2zPERwvnjX9Ke7E-Mf-2ELd1tbut23mbKYpXSXH0lIOAFQnrwfonOaq4np4WztNOX5T4.wrBMswEacn4pfixDjRlhv2_T6bhTNv02JKGWJOoCHCw&dib_tag=se&keywords=toilet+rolls+3ply&qid=1781348762&xpid=FjHbdT4PCS1_n | F22: 14.99 | H22: =IF(F22="","",IF(G22="",F22,G22)) -> 14.99 | I22: Standalone order | J22: 0 | K22: 0 | L22: =IF(H22="","",IF(I22="Grocery add-on",H22,H22+N(J22)+N(K22))) -> 14.99 | M22: 45 | N22: 150 | O22: =IF(OR(M22="",N22=""),"",M22*N22) -> 6750 | P22: 3 | S22: =IF(OR(Q22="",R22=""),"",Q22*R22/1000000) | T22: =IF(OR(O22="",S22=""),"",O22*S22) | U22: =IFERROR(L22/M22,"") -> 0.33311111 | V22: =IFERROR(L22/O22*100,"") -> 0.22207407 | W22: =IFERROR(L22/T22,"") | X22: 4 | Y22: 34 | Z22: Yes | AA22: Yes | AB22: Direct | AC22: =IF(A22="","",IF(AND(H22<>"",M22<>"",N22<>"",P22=3,Z22="Yes",AA22="Yes"),"High",IF(AND(H22<>"",M22<>"",N22<>""),"Medium","Low"))) -> High | AD22: =IF(AND(P22>=3,Z22="Yes",AA22="Yes",O22<>"",L22<>""),"Include","Exclude") -> Include | AE22: =IF(A22="","",IF(OR(ListingsTable[[#This Row],[rating]]="",ListingsTable[[#This Row],[review_count]]=""),1.03,IF(ListingsTable[[#This Row],[review_count]]<10,1,IF(ListingsTable[[#This Row],[rating]]>=4.5,0.95,IF(ListingsTable[[#This Row],[rating]]>=4,1,IF(ListingsTable[[#This Row],[rating]]<3.8,1.05,1)))))) -> 1 | AF22: =IF(AD22="Include",V22*AE22,"") -> 0.22207407 | AG22: =IF(AF22="","",COUNTIFS($AF$2:$AF$76,"<"&AF22,$AD$2:$AD$76,"Include")+COUNTIFS($AF$2:AF22,AF22,$AD$2:AD22,"Include")) -> 21
A23: 46185 | B23: Sainsbury's | C23: Sainsbury's Super Soft Toilet Tissue, Quilted | D23: Sainsbury's | E23: https://www.sainsburys.co.uk/gol-ui/product/sainsburys-super-soft-toilet-tissue-quilted-x9-rolls | F23: 4 | G23: 3.5 | H23: =IF(F23="","",IF(G23="",F23,G23)) -> 3.5 | I23: Standalone order | J23: 0 | K23: 0 | L23: =IF(H23="","",IF(I23="Grocery add-on",H23,H23+N(J23)+N(K23))) -> 3.5 | M23: 9 | N23: 170 | O23: =IF(OR(M23="",N23=""),"",M23*N23) -> 1530 | P23: 3 | Q23: 122 | R23: 105 | S23: =IF(OR(Q23="",R23=""),"",Q23*R23/1000000) -> 0.01281 | T23: =IF(OR(O23="",S23=""),"",O23*S23) -> 19.5993 | U23: =IFERROR(L23/M23,"") -> 0.38888889 | V23: =IFERROR(L23/O23*100,"") -> 0.22875817 | W23: =IFERROR(L23/T23,"") -> 0.17857781 | X23: 4.2 | Y23: 456 | Z23: Yes | AA23: Yes | AB23: Direct | AC23: =IF(A23="","",IF(AND(H23<>"",M23<>"",N23<>"",P23=3,Z23="Yes",AA23="Yes"),"High",IF(AND(H23<>"",M23<>"",N23<>""),"Medium","Low"))) -> High | AD23: =IF(AND(P23>=3,Z23="Yes",AA23="Yes",O23<>"",L23<>""),"Include","Exclude") -> Include | AE23: =IF(A23="","",IF(OR(ListingsTable[[#This Row],[rating]]="",ListingsTable[[#This Row],[review_count]]=""),1.03,IF(ListingsTable[[#This Row],[review_count]]<10,1,IF(ListingsTable[[#This Row],[rating]]>=4.5,0.95,IF(ListingsTable[[#This Row],[rating]]>=4,1,IF(ListingsTable[[#This Row],[rating]]<3.8,1.05,1)))))) -> 1 | AF23: =IF(AD23="Include",V23*AE23,"") -> 0.22875817 | AG23: =IF(AF23="","",COUNTIFS($AF$2:$AF$76,"<"&AF23,$AD$2:$AD$76,"Include")+COUNTIFS($AF$2:AF23,AF23,$AD$2:AD23,"Include")) -> 22
A24: 46188 | B24: Amazon | C24: Regina Gentle Soft Toilet Tissue | D24: Regina | E24: https://www.amazon.co.uk/Regina-Gentle-Soft-Toilet-Tissue/dp/B0D986KBXQ/ref=sr_1_41?dib=eyJ2IjoiMSJ9.0VrQIYFNkddqjafxnBR4YTeWgT5cLGR5Y8SPipAYeZS7pFul15p3BNZPd_roKbmNl9KhjGGNEDuDFHWeP6gZK3n554gP9GbeOL7U6C9yEYVshr-m1kTidS7YVXLWWw8AaLPFGJWLKYZq4oftUEF_sYbAfbLrgnQChJRXcNYBXpD8kBom22EdiTv9sy8TAzYdXzr7vaec0trGkYXh8cxLh-UrEUvkYocXltZ4T1_IDxgnO91LF_hDl_Gv_unq777iVpJKCaDCRyz2vRRT3upJJXWAGp_rvuI7HVkbnVW4ZZM.Z9LHQyKSlJpjdNFJrgAVwXrwtwqWXrNRFB5oyJ00uso&dib_tag=se&keywords=toilet%2Brolls%2B3ply&qid=1781348685&sr=8-41&th=1 | F24: 17.72 | H24: =IF(F24="","",IF(G24="",F24,G24)) -> 17.72 | I24: Standalone order | J24: 0 | K24: 0 | L24: =IF(H24="","",IF(I24="Grocery add-on",H24,H24+N(J24)+N(K24))) -> 17.72 | M24: 45 | N24: 160 | O24: =IF(OR(M24="",N24=""),"",M24*N24) -> 7200 | P24: 3 | S24: =IF(OR(Q24="",R24=""),"",Q24*R24/1000000) | T24: =IF(OR(O24="",S24=""),"",O24*S24) | U24: =IFERROR(L24/M24,"") -> 0.39377778 | V24: =IFERROR(L24/O24*100,"") -> 0.24611111 | W24: =IFERROR(L24/T24,"") | X24: 4.5 | Y24: 583 | Z24: Yes | AA24: Yes | AB24: Direct | AC24: =IF(A24="","",IF(AND(H24<>"",M24<>"",N24<>"",P24=3,Z24="Yes",AA24="Yes"),"High",IF(AND(H24<>"",M24<>"",N24<>""),"Medium","Low"))) -> High | AD24: =IF(AND(P24>=3,Z24="Yes",AA24="Yes",O24<>"",L24<>""),"Include","Exclude") -> Include | AE24: =IF(A24="","",IF(OR(ListingsTable[[#This Row],[rating]]="",ListingsTable[[#This Row],[review_count]]=""),1.03,IF(ListingsTable[[#This Row],[review_count]]<10,1,IF(ListingsTable[[#This Row],[rating]]>=4.5,0.95,IF(ListingsTable[[#This Row],[rating]]>=4,1,IF(ListingsTable[[#This Row],[rating]]<3.8,1.05,1)))))) -> 0.95 | AF24: =IF(AD24="Include",V24*AE24,"") -> 0.23380556 | AG24: =IF(AF24="","",COUNTIFS($AF$2:$AF$76,"<"&AF24,$AD$2:$AD$76,"Include")+COUNTIFS($AF$2:AF24,AF24,$AD$2:AD24,"Include")) -> 23
A25: 46188 | B25: Amazon | C25: Elegance Feather Soft Toilet Roll | D25: Elegance | E25: https://www.amazon.co.uk/Elegance-Feather-Soft-Toilet-Roll/dp/B09HN3DPM7/ref=sr_1_53?dib=eyJ2IjoiMSJ9.nXBnNjeF16M4nsl9eEL0oGARWN62HpptKIf3Evt45TLYLzWAe2Ia4SBaEoQE3m0ZCSEC3ZAdclnGN3VZVjEDsLN7olk95VSUBkM_oaV0VVY.ZA0NA1gOjeR1KMpxlTrecq1BHx250pbYygGh43JvK88&dib_tag=se&keywords=toilet+rolls+3ply&qid=1781348762&xpid=FjHbdT4PCS1_n | F25: 18.96 | H25: =IF(F25="","",IF(G25="",F25,G25)) -> 18.96 | I25: Standalone order | J25: 0 | K25: 0 | L25: =IF(H25="","",IF(I25="Grocery add-on",H25,H25+N(J25)+N(K25))) -> 18.96 | M25: 54 | N25: 150 | O25: =IF(OR(M25="",N25=""),"",M25*N25) -> 8100 | P25: 3 | S25: =IF(OR(Q25="",R25=""),"",Q25*R25/1000000) | T25: =IF(OR(O25="",S25=""),"",O25*S25) | U25: =IFERROR(L25/M25,"") -> 0.35111111 | V25: =IFERROR(L25/O25*100,"") -> 0.23407407 | W25: =IFERROR(L25/T25,"") | X25: 4.3 | Y25: 1690 | Z25: Yes | AA25: Yes | AB25: Direct | AC25: =IF(A25="","",IF(AND(H25<>"",M25<>"",N25<>"",P25=3,Z25="Yes",AA25="Yes"),"High",IF(AND(H25<>"",M25<>"",N25<>""),"Medium","Low"))) -> High | AD25: =IF(AND(P25>=3,Z25="Yes",AA25="Yes",O25<>"",L25<>""),"Include","Exclude") -> Include | AE25: =IF(A25="","",IF(OR(ListingsTable[[#This Row],[rating]]="",ListingsTable[[#This Row],[review_count]]=""),1.03,IF(ListingsTable[[#This Row],[review_count]]<10,1,IF(ListingsTable[[#This Row],[rating]]>=4.5,0.95,IF(ListingsTable[[#This Row],[rating]]>=4,1,IF(ListingsTable[[#This Row],[rating]]<3.8,1.05,1)))))) -> 1 | AF25: =IF(AD25="Include",V25*AE25,"") -> 0.23407407 | AG25: =IF(AF25="","",COUNTIFS($AF$2:$AF$76,"<"&AF25,$AD$2:$AD$76,"Include")+COUNTIFS($AF$2:AF25,AF25,$AD$2:AD25,"Include")) -> 24
A26: 46184 | B26: Amazon | C26: Velvet Classic Quilted Toilet Tissue | D26: Velvet Classic | E26: https://www.amazon.co.uk/Triple-Velvet-Jumbo-Roll-Pack/dp/B08HLGKP9J/ref=sr_1_6?crid=39Z2ZQYPKD56F&dib=eyJ2IjoiMSJ9.0VrQIYFNkddqjafxnBR4YUpARflxws9qv4GIdcGxlnf1O_12yUDai8SSTxUcgTqQfxxmeegDVzJczEpvCzyDs3Y-PnXzjiGrq46f6qn2KJ0_-8V4aaeXnv0STZK7LKw-olD0Qabt8KXEX2ZFciLnZauSAAfich8Njuv1TzYPG6vpde9sZUAvJiOmcQ3ZhotVJu8dXY8jEYsC5ozBSAKrT5RPPaiKVdv1dnDpC_MyMg_9M1a4xOcR77elQGiZh3F-OePqaMju4FowviGGVVF1RSF0nRsf-u6DdNZR6qSSS20.cfxODHL7nFlggd63AaJRjANbaVdgKaPBOM57-4dX7bM&dib_tag=se&keywords=3%2Bply%2Btoilet%2Brolls&qid=1781196830&rdc=1&sprefix=3%2Bply%2B%2Caps%2C231&sr=8-6&th=1 | F26: 8.5 | H26: =IF(F26="","",IF(G26="",F26,G26)) -> 8.5 | I26: Standalone order | J26: 0 | K26: 0 | L26: =IF(H26="","",IF(I26="Grocery add-on",H26,H26+N(J26)+N(K26))) -> 8.5 | M26: 24 | N26: 150 | O26: =IF(OR(M26="",N26=""),"",M26*N26) -> 3600 | P26: 3 | S26: =IF(OR(Q26="",R26=""),"",Q26*R26/1000000) | T26: =IF(OR(O26="",S26=""),"",O26*S26) | U26: =IFERROR(L26/M26,"") -> 0.35416667 | V26: =IFERROR(L26/O26*100,"") -> 0.23611111 | W26: =IFERROR(L26/T26,"") | X26: 4.3 | Y26: 22761 | Z26: Yes | AA26: Yes | AB26: Direct | AC26: =IF(A26="","",IF(AND(H26<>"",M26<>"",N26<>"",P26=3,Z26="Yes",AA26="Yes"),"High",IF(AND(H26<>"",M26<>"",N26<>""),"Medium","Low"))) -> High | AD26: =IF(AND(P26>=3,Z26="Yes",AA26="Yes",O26<>"",L26<>""),"Include","Exclude") -> Include | AE26: =IF(A26="","",IF(OR(ListingsTable[[#This Row],[rating]]="",ListingsTable[[#This Row],[review_count]]=""),1.03,IF(ListingsTable[[#This Row],[review_count]]<10,1,IF(ListingsTable[[#This Row],[rating]]>=4.5,0.95,IF(ListingsTable[[#This Row],[rating]]>=4,1,IF(ListingsTable[[#This Row],[rating]]<3.8,1.05,1)))))) -> 1 | AF26: =IF(AD26="Include",V26*AE26,"") -> 0.23611111 | AG26: =IF(AF26="","",COUNTIFS($AF$2:$AF$76,"<"&AF26,$AD$2:$AD$76,"Include")+COUNTIFS($AF$2:AF26,AF26,$AD$2:AD26,"Include")) -> 25
A27: 46188 | B27: Amazon | C27: by Amazon Mega Toilet Roll | D27: Amazon | E27: http://amazon.co.uk/Amazon-Toilet-Rolls-Coconut-Sheets/dp/B0DSX5ZGSW/ref=sr_1_31?dib=eyJ2IjoiMSJ9.0VrQIYFNkddqjafxnBR4YTeWgT5cLGR5Y8SPipAYeZS7pFul15p3BNZPd_roKbmNl9KhjGGNEDuDFHWeP6gZK3n554gP9GbeOL7U6C9yEYVshr-m1kTidS7YVXLWWw8AaLPFGJWLKYZq4oftUEF_sYbAfbLrgnQChJRXcNYBXpD8kBom22EdiTv9sy8TAzYdXzr7vaec0trGkYXh8cxLh-UrEUvkYocXltZ4T1_IDxgnO91LF_hDl_Gv_unq777iVpJKCaDCRyz2vRRT3upJJXWAGp_rvuI7HVkbnVW4ZZM.Z9LHQyKSlJpjdNFJrgAVwXrwtwqWXrNRFB5oyJ00uso&dib_tag=se&keywords=toilet%2Brolls%2B3ply&qid=1781348685&rdc=1&sr=8-31&th=1 | F27: 4.69 | H27: =IF(F27="","",IF(G27="",F27,G27)) -> 4.69 | I27: Standalone order | J27: 0 | K27: 0 | L27: =IF(H27="","",IF(I27="Grocery add-on",H27,H27+N(J27)+N(K27))) -> 4.69 | M27: 6 | N27: 330 | O27: =IF(OR(M27="",N27=""),"",M27*N27) -> 1980 | P27: 3 | S27: =IF(OR(Q27="",R27=""),"",Q27*R27/1000000) | T27: =IF(OR(O27="",S27=""),"",O27*S27) | U27: =IFERROR(L27/M27,"") -> 0.78166667 | V27: =IFERROR(L27/O27*100,"") -> 0.23686869 | W27: =IFERROR(L27/T27,"") | X27: 4.4 | Y27: 241 | Z27: Yes | AA27: Yes | AB27: Direct | AC27: =IF(A27="","",IF(AND(H27<>"",M27<>"",N27<>"",P27=3,Z27="Yes",AA27="Yes"),"High",IF(AND(H27<>"",M27<>"",N27<>""),"Medium","Low"))) -> High | AD27: =IF(AND(P27>=3,Z27="Yes",AA27="Yes",O27<>"",L27<>""),"Include","Exclude") -> Include | AE27: =IF(A27="","",IF(OR(ListingsTable[[#This Row],[rating]]="",ListingsTable[[#This Row],[review_count]]=""),1.03,IF(ListingsTable[[#This Row],[review_count]]<10,1,IF(ListingsTable[[#This Row],[rating]]>=4.5,0.95,IF(ListingsTable[[#This Row],[rating]]>=4,1,IF(ListingsTable[[#This Row],[rating]]<3.8,1.05,1)))))) -> 1 | AF27: =IF(AD27="Include",V27*AE27,"") -> 0.23686869 | AG27: =IF(AF27="","",COUNTIFS($AF$2:$AF$76,"<"&AF27,$AD$2:$AD$76,"Include")+COUNTIFS($AF$2:AF27,AF27,$AD$2:AD27,"Include")) -> 26
A28: 46184 | B28: Amazon | C28: by Amazon Super Soft Toilet Tissue | D28: Amazon | E28: https://www.amazon.co.uk/Presto-Quilted-Toilet-Tissues-Pattern/dp/B08KHBYPJB/ref=sr_1_1_ffob_sspa?crid=39Z2ZQYPKD56F&dib=eyJ2IjoiMSJ9.0VrQIYFNkddqjafxnBR4YUpARflxws9qv4GIdcGxlnf1O_12yUDai8SSTxUcgTqQfxxmeegDVzJczEpvCzyDs3Y-PnXzjiGrq46f6qn2KJ0_-8V4aaeXnv0STZK7LKw-olD0Qabt8KXEX2ZFciLnZauSAAfich8Njuv1TzYPG6vpde9sZUAvJiOmcQ3ZhotVJu8dXY8jEYsC5ozBSAKrT5RPPaiKVdv1dnDpC_MyMg_9M1a4xOcR77elQGiZh3F-OePqaMju4FowviGGVVF1RSF0nRsf-u6DdNZR6qSSS20.cfxODHL7nFlggd63AaJRjANbaVdgKaPBOM57-4dX7bM&dib_tag=se&keywords=3%2Bply%2Btoilet%2Brolls&qid=1781196830&rdc=1&sprefix=3%2Bply%2B%2Caps%2C231&sr=8-1-spons&aref=nsaAruaOjI&sp_csd=d2lkZ2V0TmFtZT1zcF9hdGY&th=1 | F28: 4.5 | H28: =IF(F28="","",IF(G28="",F28,G28)) -> 4.5 | I28: Standalone order | J28: 0 | K28: 0 | L28: =IF(H28="","",IF(I28="Grocery add-on",H28,H28+N(J28)+N(K28))) -> 4.5 | M28: 9 | N28: 200 | O28: =IF(OR(M28="",N28=""),"",M28*N28) -> 1800 | P28: 3 | S28: =IF(OR(Q28="",R28=""),"",Q28*R28/1000000) | T28: =IF(OR(O28="",S28=""),"",O28*S28) | U28: =IFERROR(L28/M28,"") -> 0.5 | V28: =IFERROR(L28/O28*100,"") -> 0.25 | W28: =IFERROR(L28/T28,"") | X28: 4.5 | Y28: 9606 | Z28: Yes | AA28: Yes | AB28: Direct | AC28: =IF(A28="","",IF(AND(H28<>"",M28<>"",N28<>"",P28=3,Z28="Yes",AA28="Yes"),"High",IF(AND(H28<>"",M28<>"",N28<>""),"Medium","Low"))) -> High | AD28: =IF(AND(P28>=3,Z28="Yes",AA28="Yes",O28<>"",L28<>""),"Include","Exclude") -> Include | AE28: =IF(A28="","",IF(OR(ListingsTable[[#This Row],[rating]]="",ListingsTable[[#This Row],[review_count]]=""),1.03,IF(ListingsTable[[#This Row],[review_count]]<10,1,IF(ListingsTable[[#This Row],[rating]]>=4.5,0.95,IF(ListingsTable[[#This Row],[rating]]>=4,1,IF(ListingsTable[[#This Row],[rating]]<3.8,1.05,1)))))) -> 0.95 | AF28: =IF(AD28="Include",V28*AE28,"") -> 0.2375 | AG28: =IF(AF28="","",COUNTIFS($AF$2:$AF$76,"<"&AF28,$AD$2:$AD$76,"Include")+COUNTIFS($AF$2:AF28,AF28,$AD$2:AD28,"Include")) -> 27
A29: 46188 | B29: Amazon | C29: Bumboo Essentials Toilet Roll 48 Pack | D29: Bumboo | E29: https://www.amazon.co.uk/Bumboo-Wrapped-Plastic-Free-Eco-Friendly-Biodegradable/dp/B0CVQVHBH6/ref=sr_1_113?dib=eyJ2IjoiMSJ9.0aKA_PMLIKi2qGTchC6dPM5zhv8QsLw5eUUuDlCSE_fciUTE0oVddZ7NNloM0K-kT9TfCodEDyPi97i00T3eKQDFnA5_sVmcnAjpT7sw9YeRI-stOQCHUaKr9uHkw8uLqJaQbjwE3RYh-mL_1dAvjGWh3f9KlQ0Tf_-utSX-4MrlcYA5jXUL5eeX2WJNsr6V00EpqfrEXfjbhCqqZfmmG3pFt9JnDVJmN3he0e56IBi-Ou8B8eM1tIoPirzfizNAfJbmX96Q6ofLwnboOt2irCSCGUCqO7ZPjjqn83S6mnY.w6hjR7-hjluwhACGaPledFpWgPZmiomJwu0HguJEeWc&dib_tag=se&keywords=toilet+rolls+3ply&qid=1781537902&xpid=FjHbdT4PCS1_n | F29: 34.99 | H29: =IF(F29="","",IF(G29="",F29,G29)) -> 34.99 | I29: Standalone order | J29: 0 | K29: 0 | L29: =IF(H29="","",IF(I29="Grocery add-on",H29,H29+N(J29)+N(K29))) -> 34.99 | M29: 48 | N29: 300 | O29: =IF(OR(M29="",N29=""),"",M29*N29) -> 14400 | P29: 3 | S29: =IF(OR(Q29="",R29=""),"",Q29*R29/1000000) | T29: =IF(OR(O29="",S29=""),"",O29*S29) | U29: =IFERROR(L29/M29,"") -> 0.72895833 | V29: =IFERROR(L29/O29*100,"") -> 0.24298611 | W29: =IFERROR(L29/T29,"") | X29: 4.4 | Y29: 109 | Z29: Yes | AA29: Yes | AB29: Direct | AC29: =IF(A29="","",IF(AND(H29<>"",M29<>"",N29<>"",P29=3,Z29="Yes",AA29="Yes"),"High",IF(AND(H29<>"",M29<>"",N29<>""),"Medium","Low"))) -> High | AD29: =IF(AND(P29>=3,Z29="Yes",AA29="Yes",O29<>"",L29<>""),"Include","Exclude") -> Include | AE29: =IF(A29="","",IF(OR(ListingsTable[[#This Row],[rating]]="",ListingsTable[[#This Row],[review_count]]=""),1.03,IF(ListingsTable[[#This Row],[review_count]]<10,1,IF(ListingsTable[[#This Row],[rating]]>=4.5,0.95,IF(ListingsTable[[#This Row],[rating]]>=4,1,IF(ListingsTable[[#This Row],[rating]]<3.8,1.05,1)))))) -> 1 | AF29: =IF(AD29="Include",V29*AE29,"") -> 0.24298611 | AG29: =IF(AF29="","",COUNTIFS($AF$2:$AF$76,"<"&AF29,$AD$2:$AD$76,"Include")+COUNTIFS($AF$2:AF29,AF29,$AD$2:AD29,"Include")) -> 28
A30: 46185 | B30: Ocado | C30: Velvet Classic Quilted Toilet Rolls | D30: Velvet Classic | E30: https://www.ocado.com/products/velvet-classic-quilted-toilet-rolls/520831011?srsltid=AfmBOorZoSGu1fwrE36YBEOmI0VNS-qP6Tj_4hmBriJ8VPmDqeIfXAER | F30: 8.5 | H30: =IF(F30="","",IF(G30="",F30,G30)) -> 8.5 | I30: Standalone order | J30: 0 | K30: 0 | L30: =IF(H30="","",IF(I30="Grocery add-on",H30,H30+N(J30)+N(K30))) -> 8.5 | M30: 24 | N30: 150 | O30: =IF(OR(M30="",N30=""),"",M30*N30) -> 3600 | P30: 3 | S30: =IF(OR(Q30="",R30=""),"",Q30*R30/1000000) | T30: =IF(OR(O30="",S30=""),"",O30*S30) | U30: =IFERROR(L30/M30,"") -> 0.35416667 | V30: =IFERROR(L30/O30*100,"") -> 0.23611111 | W30: =IFERROR(L30/T30,"") | Z30: Yes | AA30: Yes | AB30: Direct | AC30: =IF(A30="","",IF(AND(H30<>"",M30<>"",N30<>"",P30=3,Z30="Yes",AA30="Yes"),"High",IF(AND(H30<>"",M30<>"",N30<>""),"Medium","Low"))) -> High | AD30: =IF(AND(P30>=3,Z30="Yes",AA30="Yes",O30<>"",L30<>""),"Include","Exclude") -> Include | AE30: =IF(A30="","",IF(OR(ListingsTable[[#This Row],[rating]]="",ListingsTable[[#This Row],[review_count]]=""),1.03,IF(ListingsTable[[#This Row],[review_count]]<10,1,IF(ListingsTable[[#This Row],[rating]]>=4.5,0.95,IF(ListingsTable[[#This Row],[rating]]>=4,1,IF(ListingsTable[[#This Row],[rating]]<3.8,1.05,1)))))) -> 1.03 | AF30: =IF(AD30="Include",V30*AE30,"") -> 0.24319444 | AG30: =IF(AF30="","",COUNTIFS($AF$2:$AF$76,"<"&AF30,$AD$2:$AD$76,"Include")+COUNTIFS($AF$2:AF30,AF30,$AD$2:AD30,"Include")) -> 29
A31: 46185 | B31: Tesco Marketplace | C31: Splesh Quilted Luna Bloom 3-Ply Luxury Scented Toilet Tissue Paper | D31: Splesh | E31: https://www.tesco.com/shop/en-GB/products/325644633?seller=trn:tesco:seller:uuid:3ca332f5-c2df-406a-af90-1e145d277929&_gl=1*1pg7u36*_up*MQ..*_ga*Njg3NDQwODQyLjE3ODEzMDY1OTI.*_ga_H653QXESTP*czE3ODEzMDY1ODkkbzEkZzAkdDE3ODEzMDY1OTEkajU4JGwwJGg2MzYzNjI3Mjg.*_ga_33B19D36CY*czE3ODEzMDY1OTEkbzEkZzEkdDE3ODEzMDY2MTYkajM1JGwwJGgxNTA2NjcyMjk0 | F31: 25.69 | H31: =IF(F31="","",IF(G31="",F31,G31)) -> 25.69 | I31: Standalone order | J31: 0 | K31: 0 | L31: =IF(H31="","",IF(I31="Grocery add-on",H31,H31+N(J31)+N(K31))) -> 25.69 | M31: 72 | N31: 150 | O31: =IF(OR(M31="",N31=""),"",M31*N31) -> 10800 | P31: 3 | S31: =IF(OR(Q31="",R31=""),"",Q31*R31/1000000) | T31: =IF(OR(O31="",S31=""),"",O31*S31) | U31: =IFERROR(L31/M31,"") -> 0.35680556 | V31: =IFERROR(L31/O31*100,"") -> 0.23787037 | W31: =IFERROR(L31/T31,"") | Z31: Yes | AA31: Yes | AB31: Direct | AC31: =IF(A31="","",IF(AND(H31<>"",M31<>"",N31<>"",P31=3,Z31="Yes",AA31="Yes"),"High",IF(AND(H31<>"",M31<>"",N31<>""),"Medium","Low"))) -> High | AD31: =IF(AND(P31>=3,Z31="Yes",AA31="Yes",O31<>"",L31<>""),"Include","Exclude") -> Include | AE31: =IF(A31="","",IF(OR(ListingsTable[[#This Row],[rating]]="",ListingsTable[[#This Row],[review_count]]=""),1.03,IF(ListingsTable[[#This Row],[review_count]]<10,1,IF(ListingsTable[[#This Row],[rating]]>=4.5,0.95,IF(ListingsTable[[#This Row],[rating]]>=4,1,IF(ListingsTable[[#This Row],[rating]]<3.8,1.05,1)))))) -> 1.03 | AF31: =IF(AD31="Include",V31*AE31,"") -> 0.24500648 | AG31: =IF(AF31="","",COUNTIFS($AF$2:$AF$76,"<"&AF31,$AD$2:$AD$76,"Include")+COUNTIFS($AF$2:AF31,AF31,$AD$2:AD31,"Include")) -> 30
A32: 46185 | B32: Costco | C32: Kirkland Signature Triple Satin 3-Ply Toilet Tissue | D32: Kirkland | E32: https://www.costco.co.uk/Business-Office-Supplies/Cleaning-Care/Paper-Products-Tissues-Wipes/Kirkland-Signature-Triple-Satin-3-Ply-Toilet-Tissue-40-Rolls/p/1128517?srsltid=AfmBOoqmYlXRPLWT0RYbbH9VTMf5uvK_Cg43AuXnsoffz-WebjWHKLNg | F32: 22.99 | H32: =IF(F32="","",IF(G32="",F32,G32)) -> 22.99 | I32: Standalone order | J32: 0 | K32: 0 | L32: =IF(H32="","",IF(I32="Grocery add-on",H32,H32+N(J32)+N(K32))) -> 22.99 | M32: 40 | N32: 240 | O32: =IF(OR(M32="",N32=""),"",M32*N32) -> 9600 | P32: 3 | Q32: 108 | R32: 124 | S32: =IF(OR(Q32="",R32=""),"",Q32*R32/1000000) -> 0.013392 | T32: =IF(OR(O32="",S32=""),"",O32*S32) -> 128.5632 | U32: =IFERROR(L32/M32,"") -> 0.57475 | V32: =IFERROR(L32/O32*100,"") -> 0.23947917 | W32: =IFERROR(L32/T32,"") -> 0.17882256 | Z32: Yes | AA32: Yes | AB32: Direct | AC32: =IF(A32="","",IF(AND(H32<>"",M32<>"",N32<>"",P32=3,Z32="Yes",AA32="Yes"),"High",IF(AND(H32<>"",M32<>"",N32<>""),"Medium","Low"))) -> High | AD32: =IF(AND(P32>=3,Z32="Yes",AA32="Yes",O32<>"",L32<>""),"Include","Exclude") -> Include | AE32: =IF(A32="","",IF(OR(ListingsTable[[#This Row],[rating]]="",ListingsTable[[#This Row],[review_count]]=""),1.03,IF(ListingsTable[[#This Row],[review_count]]<10,1,IF(ListingsTable[[#This Row],[rating]]>=4.5,0.95,IF(ListingsTable[[#This Row],[rating]]>=4,1,IF(ListingsTable[[#This Row],[rating]]<3.8,1.05,1)))))) -> 1.03 | AF32: =IF(AD32="Include",V32*AE32,"") -> 0.24666354 | AG32: =IF(AF32="","",COUNTIFS($AF$2:$AF$76,"<"&AF32,$AD$2:$AD$76,"Include")+COUNTIFS($AF$2:AF32,AF32,$AD$2:AD32,"Include")) -> 31
A33: 46185 | B33: Amazon | C33: Splesh by Cusheen 3-ply Toilet Roll | D33: Splesh | E33: https://www.amazon.co.uk/gp/aw/d/B06WD1FD7Y/?_encoding=UTF8&pd_rd_plhdr=t&aaxitk=101b04a4f3fb704f0d23b387fae62410&hsa_cr_id=0&qid=1781348685&sr=1-1-1ee1b2e4-01d1-4cd0-b737-4c27ebfc8105&aref=frIjszFI2Q&ref_=sbx__sbtcd2_asin_0_img&pf_rd_p=ad0b5640-22e8-4858-8c86-e8809057e952&pf_rd_r=X7B60P4ED0BWN59HGRMK&pd_rd_wg=UGclu&pd_rd_w=GRWHU&content-id=amzn1.sym.ad0b5640-22e8-4858-8c86-e8809057e952%3Aamzn1.sym.ad0b5640-22e8-4858-8c86-e8809057e952&pd_rd_r=f0428668-d3cf-4e15-97ef-cf24bc2f1421&th=1 | F33: 22.99 | H33: =IF(F33="","",IF(G33="",F33,G33)) -> 22.99 | I33: Standalone order | J33: 0 | K33: 0 | L33: =IF(H33="","",IF(I33="Grocery add-on",H33,H33+N(J33)+N(K33))) -> 22.99 | M33: 60 | N33: 150 | O33: =IF(OR(M33="",N33=""),"",M33*N33) -> 9000 | P33: 3 | S33: =IF(OR(Q33="",R33=""),"",Q33*R33/1000000) | T33: =IF(OR(O33="",S33=""),"",O33*S33) | U33: =IFERROR(L33/M33,"") -> 0.38316667 | V33: =IFERROR(L33/O33*100,"") -> 0.25544444 | W33: =IFERROR(L33/T33,"") | X33: 4.4 | Y33: 10165 | Z33: Yes | AA33: Yes | AB33: Direct | AC33: =IF(A33="","",IF(AND(H33<>"",M33<>"",N33<>"",P33=3,Z33="Yes",AA33="Yes"),"High",IF(AND(H33<>"",M33<>"",N33<>""),"Medium","Low"))) -> High | AD33: =IF(AND(P33>=3,Z33="Yes",AA33="Yes",O33<>"",L33<>""),"Include","Exclude") -> Include | AE33: =IF(A33="","",IF(OR(ListingsTable[[#This Row],[rating]]="",ListingsTable[[#This Row],[review_count]]=""),1.03,IF(ListingsTable[[#This Row],[review_count]]<10,1,IF(ListingsTable[[#This Row],[rating]]>=4.5,0.95,IF(ListingsTable[[#This Row],[rating]]>=4,1,IF(ListingsTable[[#This Row],[rating]]<3.8,1.05,1)))))) -> 1 | AF33: =IF(AD33="Include",V33*AE33,"") -> 0.25544444 | AG33: =IF(AF33="","",COUNTIFS($AF$2:$AF$76,"<"&AF33,$AD$2:$AD$76,"Include")+COUNTIFS($AF$2:AF33,AF33,$AD$2:AD33,"Include")) -> 32
A34: 46185 | B34: Tesco | C34: Tesco Luxury Soft Quilted Toilet Tissue | D34: Tesco | E34: https://www.tesco.com/shop/en-GB/products/312092758?_gl=1*1rvhuv7*_up*MQ..*_ga*Njg3NDQwODQyLjE3ODEzMDY1OTI.*_ga_H653QXESTP*czE3ODEzMDY1ODkkbzEkZzAkdDE3ODEzMDY1OTEkajU4JGwwJGg2MzYzNjI3Mjg.*_ga_33B19D36CY*czE3ODEzMDY1OTEkbzEkZzEkdDE3ODEzMDY3MzckajUyJGwwJGgxNTA2NjcyMjk0 | F34: 3.75 | H34: =IF(F34="","",IF(G34="",F34,G34)) -> 3.75 | I34: Standalone order | J34: 0 | K34: 0 | L34: =IF(H34="","",IF(I34="Grocery add-on",H34,H34+N(J34)+N(K34))) -> 3.75 | M34: 6 | N34: 240 | O34: =IF(OR(M34="",N34=""),"",M34*N34) -> 1440 | P34: 3 | S34: =IF(OR(Q34="",R34=""),"",Q34*R34/1000000) | T34: =IF(OR(O34="",S34=""),"",O34*S34) | U34: =IFERROR(L34/M34,"") -> 0.625 | V34: =IFERROR(L34/O34*100,"") -> 0.26041667 | W34: =IFERROR(L34/T34,"") | X34: 3.9 | Y34: 259 | Z34: Yes | AA34: Yes | AB34: Direct | AC34: =IF(A34="","",IF(AND(H34<>"",M34<>"",N34<>"",P34=3,Z34="Yes",AA34="Yes"),"High",IF(AND(H34<>"",M34<>"",N34<>""),"Medium","Low"))) -> High | AD34: =IF(AND(P34>=3,Z34="Yes",AA34="Yes",O34<>"",L34<>""),"Include","Exclude") -> Include | AE34: =IF(A34="","",IF(OR(ListingsTable[[#This Row],[rating]]="",ListingsTable[[#This Row],[review_count]]=""),1.03,IF(ListingsTable[[#This Row],[review_count]]<10,1,IF(ListingsTable[[#This Row],[rating]]>=4.5,0.95,IF(ListingsTable[[#This Row],[rating]]>=4,1,IF(ListingsTable[[#This Row],[rating]]<3.8,1.05,1)))))) -> 1 | AF34: =IF(AD34="Include",V34*AE34,"") -> 0.26041667 | AG34: =IF(AF34="","",COUNTIFS($AF$2:$AF$76,"<"&AF34,$AD$2:$AD$76,"Include")+COUNTIFS($AF$2:AF34,AF34,$AD$2:AD34,"Include")) -> 33
